Workbook

Sheet Participants
A1: participant_ID | B1: participant_age | C1: participant_gender | D1: participant_start_time | E1: participant_end_time | F1: duration_min | G1: mirror_words | H1: inverse_words | I1: included | J1: rejection reason | K1: gender_label | L1: mirror_order
A2: 10345 | B2: 49 | C2: 1 | D2: 1752259251374 | E2: 1752261649504 | F2: =(E2-D2)/60000 -> 39.968833 | G2: 484 | H2: 406 | I2: =IF(AND(G2>=$O$2,H2>=$O$2),1,0) -> 1 | J2: =IF(I2=1,"","too few words") | K2: =IF(C2=1,"Female",IF(C2=2,"Male","Code 3 (unconfirmed)")) -> Female | L2: 1 | N2: Word minimum (each chat) | O2: 130
A3: 11492 | B3: 47 | C3: 2 | D3: 1752262127249 | E3: 1752266549468 | F3: =(E3-D3)/60000 -> 73.70365 | G3: 596 | H3: 474 | I3: =IF(AND(G3>=$O$2,H3>=$O$2),1,0) -> 1 | J3: =IF(I3=1,"","too few words") | K3: =IF(C3=1,"Female",IF(C3=2,"Male","Code 3 (unconfirmed)")) -> Male | L3: 2 | N3: Participants included | O3: =SUM(I2:I101) -> 95
A4: 12178 | B4: 33 | C4: 1 | D4: 1752259858135 | E4: 1752264277434 | F4: =(E4-D4)/60000 -> 73.654983 | G4: 598 | H4: 669 | I4: =IF(AND(G4>=$O$2,H4>=$O$2),1,0) -> 1 | J4: =IF(I4=1,"","too few words") | K4: =IF(C4=1,"Female",IF(C4=2,"Male","Code 3 (unconfirmed)")) -> Female | L4: 1
A5: 16042 | B5: 29 | C5: 1 | D5: 1752259463691 | E5: 1752261292560 | F5: =(E5-D5)/60000 -> 30.48115 | G5: 438 | H5: 530 | I5: =IF(AND(G5>=$O$2,H5>=$O$2),1,0) -> 1 | J5: =IF(I5=1,"","too few words") | K5: =IF(C5=1,"Female",IF(C5=2,"Male","Code 3 (unconfirmed)")) -> Female | L5: 2
A6: 16234 | B6: 49 | C6: 1 | D6: 1752416886549 | E6: 1752419486647 | F6: =(E6-D6)/60000 -> 43.334967 | G6: 477 | H6: 394 | I6: =IF(AND(G6>=$O$2,H6>=$O$2),1,0) -> 1 | J6: =IF(I6=1,"","too few words") | K6: =IF(C6=1,"Female",IF(C6=2,"Male","Code 3 (unconfirmed)")) -> Female | L6: 1
A7: 17304 | B7: 34 | C7: 1 | D7: 1752416843866 | E7: 1752419639864 | F7: =(E7-D7)/60000 -> 46.599967 | G7: 243 | H7: 384 | I7: =IF(AND(G7>=$O$2,H7>=$O$2),1,0) -> 1 | J7: =IF(I7=1,"","too few words") | K7: =IF(C7=1,"Female",IF(C7=2,"Male","Code 3 (unconfirmed)")) -> Female | L7: 2
A8: 18724 | B8: 46 | C8: 1 | D8: 1752417313723 | E8: 1752422138079 | F8: =(E8-D8)/60000 -> 80.405933 | G8: 503 | H8: 480 | I8: =IF(AND(G8>=$O$2,H8>=$O$2),1,0) -> 1 | J8: =IF(I8=1,"","too few words") | K8: =IF(C8=1,"Female",IF(C8=2,"Male","Code 3 (unconfirmed)")) -> Female | L8: 1
A9: 21566 | B9: 39 | C9: 2 | D9: 1752259113581 | E9: 1752262159360 | F9: =(E9-D9)/60000 -> 50.762983 | G9: 224 | H9: 483 | I9: =IF(AND(G9>=$O$2,H9>=$O$2),1,0) -> 1 | J9: =IF(I9=1,"","too few words") | K9: =IF(C9=1,"Female",IF(C9=2,"Male","Code 3 (unconfirmed)")) -> Male | L9: 2
A10: 22826 | B10: 41 | C10: 2 | D10: 1752416813983 | E10: 1752418721926 | F10: =(E10-D10)/60000 -> 31.79905 | G10: 79 | H10: 151 | I10: =IF(AND(G10>=$O$2,H10>=$O$2),1,0) -> 0 | J10: =IF(I10=1,"","too few words") -> too few words | K10: =IF(C10=1,"Female",IF(C10=2,"Male","Code 3 (unconfirmed)")) -> Male | L10: 2
A11: 23105 | B11: 21 | C11: 1 | D11: 1752259232717 | E11: 1752262291130 | F11: =(E11-D11)/60000 -> 50.97355 | G11: 535 | H11: 532 | I11: =IF(AND(G11>=$O$2,H11>=$O$2),1,0) -> 1 | J11: =IF(I11=1,"","too few words") | K11: =IF(C11=1,"Female",IF(C11=2,"Male","Code 3 (unconfirmed)")) -> Female | L11: 1
A12: 23429 | B12: 39 | C12: 1 | D12: 1752416776963 | E12: 1752418429152 | F12: =(E12-D12)/60000 -> 27.536483 | G12: 478 | H12: 376 | I12: =IF(AND(G12>=$O$2,H12>=$O$2),1,0) -> 1 | J12: =IF(I12=1,"","too few words") | K12: =IF(C12=1,"Female",IF(C12=2,"Male","Code 3 (unconfirmed)")) -> Female | L12: 1
A13: 23564 | B13: 42 | C13: 1 | D13: 1752259603440 | E13: 1752261388802 | F13: =(E13-D13)/60000 -> 29.756033 | G13: 266 | H13: 276 | I13: =IF(AND(G13>=$O$2,H13>=$O$2),1,0) -> 1 | J13: =IF(I13=1,"","too few words") | K13: =IF(C13=1,"Female",IF(C13=2,"Male","Code 3 (unconfirmed)")) -> Female | L13: 2
A14: 24311 | B14: 35 | C14: 2 | D14: 1752259261565 | E14: 1752261359726 | F14: =(E14-D14)/60000 -> 34.96935 | G14: 377 | H14: 435 | I14: =IF(AND(G14>=$O$2,H14>=$O$2),1,0) -> 1 | J14: =IF(I14=1,"","too few words") | K14: =IF(C14=1,"Female",IF(C14=2,"Male","Code 3 (unconfirmed)")) -> Male | L14: 1
A15: 26586 | B15: 50 | C15: 1 | D15: 1752259296735 | E15: 1752263037091 | F15: =(E15-D15)/60000 -> 62.339267 | G15: 757 | H15: 649 | I15: =IF(AND(G15>=$O$2,H15>=$O$2),1,0) -> 1 | J15: =IF(I15=1,"","too few words") | K15: =IF(C15=1,"Female",IF(C15=2,"Male","Code 3 (unconfirmed)")) -> Female | L15: 2
... A101: 99496 | B101: 33 | C101: 2 | D101: 1752416887598 | E101: 1752419503633 | F101: =(E101-D101)/60000 -> 43.600583 | G101: 469 | H101: 486 | I101: =IF(AND(G101>=$O$2,H101>=$O$2),1,0) -> 1 | J101: =IF(I101=1,"","too few words") | K101: =IF(C101=1,"Female",IF(C101=2,"Male","Code 3 (unconfirmed)")) -> Male | L101: 1
B102: =MEDIAN(B2:B101) -> 34 | G102: =MEDIAN(G2:G101) -> 360.5 | H102: =MEDIAN(H2:H101) -> 386.5

Sheet BFI Scores
A1: participant_ID | B1: self_extraversion | C1: self_agreeableness | D1: self_conscientiousness | E1: self_neuroticism | F1: self_openness | G1: mirror26_extraversion | H1: mirror26_agreeableness | I1: mirror26_conscientiousness | J1: mirror26_neuroticism | K1: mirror26_openness | L1: inverse26_extraversion | M1: inverse26_agreeableness | N1: inverse26_conscientiousness | O1: inverse26_neuroticism | P1: inverse26_openness | Q1: mirrorBoW_extraversion | R1: mirrorBoW_agreeableness | S1: mirrorBoW_conscientiousness | T1: mirrorBoW_neuroticism | U1: mirrorBoW_openness | V1: inverseBoW_extraversion | W1: inverseBoW_agreeableness | X1: inverseBoW_conscientiousness | Y1: inverseBoW_neuroticism | Z1: inverseBoW_openness | AA1: mirrorPartOnly_extraversion | AB1: mirrorPartOnly_agreeableness | AC1: mirrorPartOnly_conscientiousness | AD1: mirrorPartOnly_neuroticism | AE1: mirrorPartOnly_openness | AF1: inversePartOnly_extraversion | AG1: inversePartOnly_agreeableness | AH1: inversePartOnly_conscientiousness | AI1: inversePartOnly_neuroticism | AJ1: inversePartOnly_openness | AL1: Notes
A2: 10345 | B2: 4.75 | C2: 4.56 | D2: 4.89 | E2: 2 | F2: 4.3 | G2: 3.875 | H2: 4.4888889 | I2: 2.8666667 | J2: 1.65 | K2: 3.88 | L2: 3.9625 | M2: 4.1 | N2: 3.3777778 | O2: 1.7625 | P2: 3.48 | Q2: 4.325 | R2: 4.3222222 | S2: 2.6222222 | T2: 1.8375 | U2: 4.02 | V2: 4.4375 | W2: 3.5111111 | X2: 2.1222222 | Y2: 2.9375 | Z2: 3.42 | AA2: 3.9625 | AB2: 4.4444444 | AC2: 2.2333333 | AD2: 1.8125 | AE2: 4.2 | AF2: 4.7375 | AG2: 3.8 | AH2: 2.5333333 | AI2: 1.9125 | AJ2: 3.29 | AL2: Self = self report
A3: 11492 | B3: 4 | C3: 5 | D3: 5 | E3: 1.25 | F3: 4.6 | G3: 4.3375 | H3: 5 | I3: 3.7888889 | J3: 1.1125 | K3: 3.27 | L3: 3.5875 | M3: 4.0888889 | N3: 4.3444444 | O3: 1.075 | P3: 2.9 | Q3: 3.95 | R3: 4.5555556 | S3: 3.1111111 | T3: 2.65 | U3: 3.55 | V3: 3.05 | W3: 3.9111111 | X3: 3.8333333 | Y3: 3.5875 | Z3: 2.94 | AA3: 4.85 | AB3: 4.9777778 | AC3: 3.1666667 | AD3: 1.075 | AE3: 3.09 | AF3: 4.0125 | AG3: 4.0111111 | AH3: 3.5777778 | AI3: 1.1375 | AJ3: 2.74 | AL3: BoW = content words and pronouns
A4: 12178 | B4: 2 | C4: 4.22 | D4: 5 | E4: 2.13 | F4: 4 | G4: 3.4875 | H4: 4 | I4: 3.2222222 | J4: 2.025 | K4: 3.33 | L4: 2.725 | M4: 3.6111111 | N4: 4.6111111 | O4: 1.7125 | P4: 3.15 | Q4: 4.35 | R4: 2.2555556 | S4: 2.7444444 | T4: 3.75 | U4: 2.98 | V4: 3.8875 | W4: 2.1555556 | X4: 3.6555556 | Y4: 2.9125 | Z4: 2.9 | AA4: 3.625 | AB4: 3.8666667 | AC4: 2.7666667 | AD4: 2.7375 | AE4: 3.27 | AF4: 3.2375 | AG4: 3.1777778 | AH4: 4.2888889 | AI4: 2.075 | AJ4: 3.51
A5: 16042 | B5: 2.63 | C5: 4.78 | D5: 4.89 | E5: 1.88 | F5: 3.4 | G5: 3.575 | H5: 4.6888889 | I5: 4.1333333 | J5: 1.5375 | K5: 3.04 | L5: 2.9375 | M5: 4.5111111 | N5: 3.8 | O5: 1.9875 | P5: 3.61 | Q5: 3.8 | R5: 4.3888889 | S5: 4 | T5: 1.875 | U5: 4.01 | V5: 3 | W5: 3.5222222 | X5: 2.1444444 | Y5: 3.025 | Z5: 4.13 | AA5: 3.875 | AB5: 4.8111111 | AC5: 4.1111111 | AD5: 1.5 | AE5: 3.05 | AF5: 3.4875 | AG5: 4.4222222 | AH5: 3.1222222 | AI5: 2 | AJ5: 3.63
A6: 16234 | B6: 1.63 | C6: 4.89 | D6: 4.56 | E6: 1 | F6: 3.5 | G6: 2.1875 | H6: 3.2555556 | I6: 3.7444444 | J6: 3.8125 | K6: 2.01 | L6: 2.175 | M6: 3.2444444 | N6: 3.6777778 | O6: 3.8125 | P6: 2.78 | Q6: 2.7875 | R6: 3.5777778 | S6: 3.9555556 | T6: 3.1 | U6: 2.07 | V6: 3.2375 | W6: 2.8555556 | X6: 3.0222222 | Y6: 4.475 | Z6: 2.42 | AA6: 2.5375 | AB6: 3.4222222 | AC6: 3.4666667 | AD6: 3.65 | AE6: 2.1 | AF6: 3.0625 | AG6: 2.9666667 | AH6: 3.0111111 | AI6: 4.2625 | AJ6: 2.87
A7: 17304 | B7: 3.5 | C7: 4.67 | D7: 4.78 | E7: 1.88 | F7: 4.1 | G7: 3.175 | H7: 4.4777778 | I7: 2.4333333 | J7: 1.85 | K7: 2.9 | L7: 4 | M7: 4.7888889 | N7: 4.6333333 | O7: 1.825 | P7: 2.73 | Q7: 3.3875 | R7: 4 | S7: 2.2111111 | T7: 2.3375 | U7: 2.38 | V7: 4.4375 | W7: 4.4 | X7: 2.8222222 | Y7: 1.8875 | Z7: 2.36 | AA7: 3.725 | AB7: 4.2222222 | AC7: 2.1777778 | AD7: 2.5125 | AE7: 3.02 | AF7: 4.525 | AG7: 4.2444444 | AH7: 4.1222222 | AI7: 1.6625 | AJ7: 2.57
A8: 18724 | B8: 2.38 | C8: 3 | D8: 3.89 | E8: 3.38 | F8: 3 | G8: 2.3875 | H8: 3.5666667 | I8: 3.0666667 | J8: 1.85 | K8: 2.01 | L8: 2.225 | M8: 3.8111111 | N8: 3.8333333 | O8: 1.95 | P8: 2.44 | Q8: 3.75 | R8: 4.0111111 | S8: 3.1111111 | T8: 1.9 | U8: 3.12 | V8: 3 | W8: 3.6222222 | X8: 3.0222222 | Y8: 2.8625 | Z8: 2.7 | AA8: 2.9375 | AB8: 3.7777778 | AC8: 2.9666667 | AD8: 1.9875 | AE8: 2.09 | AF8: 2.375 | AG8: 3.7777778 | AH8: 3.0222222 | AI8: 2 | AJ8: 2.31
A9: 21566 | B9: 2.63 | C9: 2.78 | D9: 3.22 | E9: 2.25 | F9: 4.1 | G9: 3.3 | H9: 2.9 | I9: 2.3111111 | J9: 1.1875 | K9: 3.32 | L9: 3.35 | M9: 3.0888889 | N9: 3.0777778 | O9: 1.4125 | P9: 3.9 | Q9: 4.175 | R9: 2.1111111 | S9: 1.9888889 | T9: 2.625 | U9: 2.53 | V9: 4.55 | W9: 3.3555556 | X9: 2.4111111 | Y9: 3.7875 | Z9: 4.19 | AA9: 3.9875 | AB9: 2.6777778 | AC9: 2.1222222 | AD9: 1.2625 | AE9: 3.2 | AF9: 3.9125 | AG9: 3.3555556 | AH9: 2.1888889 | AI9: 1.675 | AJ9: 4.08
A10: 23105 | B10: 2.63 | C10: 3.33 | D10: 3.56 | E10: 3.38 | F10: 3 | G10: 4.625 | H10: 4.3444444 | I10: 2.9222222 | J10: 3.05 | K10: 3.01 | L10: 4.7375 | M10: 4.0888889 | N10: 2.1111111 | O10: 1.9 | P10: 2.74 | Q10: 4.4375 | R10: 3.3111111 | S10: 1.9444444 | T10: 3.75 | U10: 2.89 | V10: 4.625 | W10: 3.7888889 | X10: 1.7555556 | Y10: 3.0375 | Z10: 2.09 | AA10: 4.625 | AB10: 4.3666667 | AC10: 2.9 | AD10: 3.25 | AE10: 3.01 | AF10: 4.75 | AG10: 4.1555556 | AH10: 2.1 | AI10: 2.0875 | AJ10: 2.57
A11: 23429 | B11: 3.38 | C11: 4.44 | D11: 4 | E11: 1.5 | F11: 4 | G11: 3.0625 | H11: 4.7 | I11: 3.6444444 | J11: 1 | K11: 2.48 | L11: 3.5625 | M11: 4.2888889 | N11: 4.0777778 | O11: 1.0875 | P11: 2.34 | Q11: 3.45 | R11: 4.3666667 | S11: 3.4666667 | T11: 3.375 | U11: 3.09 | V11: 2.9625 | W11: 4.3 | X11: 3.3555556 | Y11: 3.9 | Z11: 2.47 | AA11: 3.8 | AB11: 4.8888889 | AC11: 3.4444444 | AD11: 1.05 | AE11: 2.87 | AF11: 4.8625 | AG11: 3.2444444 | AH11: 4 | AI11: 1.05 | AJ11: 2.11
A12: 23564 | B12: 2.38 | C12: 4.33 | D12: 4.56 | E12: 1.75 | F12: 4 | G12: 2.125 | H12: 3.4 | I12: 2.0444444 | J12: 2.575 | K12: 1.85 | L12: 2 | M12: 3.4222222 | N12: 3.8222222 | O12: 4.5375 | P12: 1.9 | Q12: 3.1375 | R12: 4.2555556 | S12: 2.3666667 | T12: 1.8875 | U12: 1.86 | V12: 2.225 | W12: 2.9888889 | X12: 2.4888889 | Y12: 4.9875 | Z12: 2.05 | AA12: 2.6875 | AB12: 3.7666667 | AC12: 2 | AD12: 2.675 | AE12: 1.97 | AF12: 2 | AG12: 3.3888889 | AH12: 3.4444444 | AI12: 4.625 | AJ12: 1.92
A13: 24311 | B13: 1.13 | C13: 3.22 | D13: 1.67 | E13: 4.38 | F13: 3.1 | G13: 1.6375 | H13: 3.4555556 | I13: 1.6777778 | J13: 4.45 | K13: 2.86 | L13: 2.125 | M13: 3.5 | N13: 2.8888889 | O13: 2.125 | P13: 4.36 | Q13: 3.4375 | R13: 2.7555556 | S13: 2.2777778 | T13: 3.675 | U13: 3.64 | V13: 2.8125 | W13: 2.7777778 | X13: 2.5888889 | Y13: 2.8875 | Z13: 4.36 | AA13: 1.95 | AB13: 3.4666667 | AC13: 1.5777778 | AD13: 4.05 | AE13: 3.1 | AF13: 2.8375 | AG13: 3.5222222 | AH13: 2.1111111 | AI13: 2.4625 | AJ13: 4.36
A14: 26586 | B14: 3.38 | C14: 4.67 | D14: 4.11 | E14: 2.75 | F14: 4.2 | G14: 2.95 | H14: 4.9 | I14: 3.8666667 | J14: 2.5375 | K14: 3.86 | L14: 3.3 | M14: 4.4555556 | N14: 4.0333333 | O14: 2.1625 | P14: 3.39 | Q14: 3.3 | R14: 4.7777778 | S14: 3.0111111 | T14: 1.9625 | U14: 4.66 | V14: 3.4375 | W14: 3.7222222 | X14: 3.6888889 | Y14: 3.675 | Z14: 3.93 | AA14: 3.5875 | AB14: 4.6666667 | AC14: 3.3222222 | AD14: 2.5875 | AE14: 3.83 | AF14: 3.4625 | AG14: 4.1111111 | AH14: 3.5333333 | AI14: 2.575 | AJ14: 3.45
A15: 26627 | B15: 1.75 | C15: 4.56 | D15: 4.89 | E15: 1.13 | F15: 3.5 | G15: 2.875 | H15: 4.6888889 | I15: 4.2 | J15: 3.625 | K15: 1.92 | L15: 2.875 | M15: 4.6111111 | N15: 3.9666667 | O15: 3.6375 | P15: 2.78 | Q15: 3.075 | R15: 3.7333333 | S15: 3.1111111 | T15: 4.375 | U15: 1.89 | V15: 3.375 | W15: 4.1888889 | X15: 3.1777778 | Y15: 3.7125 | Z15: 2.39 | AA15: 2.8875 | AB15: 4.6555556 | AC15: 4.0333333 | AD15: 3.625 | AE15: 1.96 | AF15: 3.525 | AG15: 4.6888889 | AH15: 3.8 | AI15: 3.725 | AJ15: 2.81
... A96: 99496 | B96: 4.5 | C96: 3.78 | D96: 5 | E96: 1.38 | F96: 3.4 | G96: 3.275 | H96: 3.6333333 | I96: 4.1111111 | J96: 1.6125 | K96: 2.61 | L96: 2.3125 | M96: 4.7888889 | N96: 3.7 | O96: 3.175 | P96: 3.5 | Q96: 3.85 | R96: 3.9777778 | S96: 4.1666667 | T96: 1.875 | U96: 2.51 | V96: 3.3 | W96: 4.4444444 | X96: 3.8777778 | Y96: 3.1375 | Z96: 3.42 | AA96: 3.6375 | AB96: 4 | AC96: 4.0333333 | AD96: 1.425 | AE96: 2.72 | AF96: 2.75 | AG96: 4.8 | AH96: 3.2111111 | AI96: 3.6375 | AJ96: 3.33

Sheet Correlations
A1: A. Predicted vs self-reported scores, by chat
A2: Condition | B2: Chat | C2: Trait | D2: n | E2: r | F2: ci_low | G2: ci_high | H2: p_parametric | I2: p_holm | J2: sig
A3: Full conversation (26 turns) | B3: Mirror | C3: Extraversion | D3: =COUNT('BFI Scores'!$G$2:$G$96) -> 95 | E3: =CORREL('BFI Scores'!$G$2:$G$96,'BFI Scores'!$B$2:$B$96) -> 0.46749577 | F3: =FISHERINV(FISHER(E3)-NORMSINV(0.975)/SQRT(D3-3)) -> 0.29361755 | G3: =FISHERINV(FISHER(E3)+NORMSINV(0.975)/SQRT(D3-3)) -> 0.61142957 | H3: =TDIST(ABS(E3)*SQRT((D3-2)/(1-E3^2)),D3-2,2) -> 1.784594e-06 | I3: 7.14e-06 | J3: ***
A4: Full conversation (26 turns) | B4: Mirror | C4: Agreeableness | D4: =COUNT('BFI Scores'!$H$2:$H$96) -> 95 | E4: =CORREL('BFI Scores'!$H$2:$H$96,'BFI Scores'!$C$2:$C$96) -> 0.35085724 | F4: =FISHERINV(FISHER(E4)-NORMSINV(0.975)/SQRT(D4-3)) -> 0.1606761 | G4: =FISHERINV(FISHER(E4)+NORMSINV(0.975)/SQRT(D4-3)) -> 0.51591822 | H4: =TDIST(ABS(E4)*SQRT((D4-2)/(1-E4^2)),D4-2,2) -> 0.00049035364 | I4: 0.000980707 | J4: ***
A5: Full conversation (26 turns) | B5: Mirror | C5: Conscientiousness | D5: =COUNT('BFI Scores'!$I$2:$I$96) -> 95 | E5: =CORREL('BFI Scores'!$I$2:$I$96,'BFI Scores'!$D$2:$D$96) -> 0.14205282 | F5: =FISHERINV(FISHER(E5)-NORMSINV(0.975)/SQRT(D5-3)) -> -0.061243575 | G5: =FISHERINV(FISHER(E5)+NORMSINV(0.975)/SQRT(D5-3)) -> 0.33403256 | H5: =TDIST(ABS(E5)*SQRT((D5-2)/(1-E5^2)),D5-2,2) -> 0.16968855 | I5: 0.16968855 | J5: ns
A6: Full conversation (26 turns) | B6: Mirror | C6: Neuroticism | D6: =COUNT('BFI Scores'!$J$2:$J$96) -> 95 | E6: =CORREL('BFI Scores'!$J$2:$J$96,'BFI Scores'!$E$2:$E$96) -> 0.62768477 | F6: =FISHERINV(FISHER(E6)-NORMSINV(0.975)/SQRT(D6-3)) -> 0.48785854 | G6: =FISHERINV(FISHER(E6)+NORMSINV(0.975)/SQRT(D6-3)) -> 0.7361063 | H6: =TDIST(ABS(E6)*SQRT((D6-2)/(1-E6^2)),D6-2,2) -> 9.9400235e-12 | I6: 4.97e-11 | J6: ***
A7: Full conversation (26 turns) | B7: Mirror | C7: Openness | D7: =COUNT('BFI Scores'!$K$2:$K$96) -> 95 | E7: =CORREL('BFI Scores'!$K$2:$K$96,'BFI Scores'!$F$2:$F$96) -> 0.41309847 | F7: =FISHERINV(FISHER(E7)-NORMSINV(0.975)/SQRT(D7-3)) -> 0.23076859 | G7: =FISHERINV(FISHER(E7)+NORMSINV(0.975)/SQRT(D7-3)) -> 0.56740129 | H7: =TDIST(ABS(E7)*SQRT((D7-2)/(1-E7^2)),D7-2,2) -> 3.1756103e-05 | I7: 9.53e-05 | J7: ***
A8: Full conversation (26 turns) | B8: Mirror | C8: Mean across traits | E8: =AVERAGE(E3:E7) -> 0.40023782 | J8: =COUNTIF(J3:J7,"<>ns")&" of 5 sig." -> 4 of 5 sig.
C9: SD | E9: =_xlfn.STDEV.S(E3:E7) -> 0.17714336
A10: Full conversation (26 turns) | B10: Inverse | C10: Extraversion | D10: =COUNT('BFI Scores'!$L$2:$L$96) -> 95 | E10: =CORREL('BFI Scores'!$L$2:$L$96,'BFI Scores'!$B$2:$B$96) -> 0.43511213 | F10: =FISHERINV(FISHER(E10)-NORMSINV(0.975)/SQRT(D10-3)) -> 0.25602054 | G10: =FISHERINV(FISHER(E10)+NORMSINV(0.975)/SQRT(D10-3)) -> 0.5853257 | H10: =TDIST(ABS(E10)*SQRT((D10-2)/(1-E10^2)),D10-2,2) -> 1.0509601e-05 | I10: 5.25e-05 | J10: ***
A11: Full conversation (26 turns) | B11: Inverse | C11: Agreeableness | D11: =COUNT('BFI Scores'!$M$2:$M$96) -> 95 | E11: =CORREL('BFI Scores'!$M$2:$M$96,'BFI Scores'!$C$2:$C$96) -> 0.30529729 | F11: =FISHERINV(FISHER(E11)-NORMSINV(0.975)/SQRT(D11-3)) -> 0.11055691 | G11: =FISHERINV(FISHER(E11)+NORMSINV(0.975)/SQRT(D11-3)) -> 0.47746182 | H11: =TDIST(ABS(E11)*SQRT((D11-2)/(1-E11^2)),D11-2,2) -> 0.0026258374 | I11: 0.007877512 | J11: **
A12: Full conversation (26 turns) | B12: Inverse | C12: Conscientiousness | D12: =COUNT('BFI Scores'!$N$2:$N$96) -> 95 | E12: =CORREL('BFI Scores'!$N$2:$N$96,'BFI Scores'!$D$2:$D$96) -> 0.1520652 | F12: =FISHERINV(FISHER(E12)-NORMSINV(0.975)/SQRT(D12-3)) -> -0.051042133 | G12: =FISHERINV(FISHER(E12)+NORMSINV(0.975)/SQRT(D12-3)) -> 0.34309319 | H12: =TDIST(ABS(E12)*SQRT((D12-2)/(1-E12^2)),D12-2,2) -> 0.14126488 | I12: 0.15000466 | J12: ns
A13: Full conversation (26 turns) | B13: Inverse | C13: Neuroticism | D13: =COUNT('BFI Scores'!$O$2:$O$96) -> 95 | E13: =CORREL('BFI Scores'!$O$2:$O$96,'BFI Scores'!$E$2:$E$96) -> 0.18354489 | F13: =FISHERINV(FISHER(E13)-NORMSINV(0.975)/SQRT(D13-3)) -> -0.01868948 | G13: =FISHERINV(FISHER(E13)+NORMSINV(0.975)/SQRT(D13-3)) -> 0.37135082 | H13: =TDIST(ABS(E13)*SQRT((D13-2)/(1-E13^2)),D13-2,2) -> 0.07500233 | I13: 0.15000466 | J13: ns
A14: Full conversation (26 turns) | B14: Inverse | C14: Openness | D14: =COUNT('BFI Scores'!$P$2:$P$96) -> 95 | E14: =CORREL('BFI Scores'!$P$2:$P$96,'BFI Scores'!$F$2:$F$96) -> 0.38528754 | F14: =FISHERINV(FISHER(E14)-NORMSINV(0.975)/SQRT(D14-3)) -> 0.19921389 | G14: =FISHERINV(FISHER(E14)+NORMSINV(0.975)/SQRT(D14-3)) -> 0.54454549 | H14: =TDIST(ABS(E14)*SQRT((D14-2)/(1-E14^2)),D14-2,2) -> 0.00011546219 | I14: 0.000461849 | J14: ***
A15: Full conversation (26 turns) | B15: Inverse | C15: Mean across traits | E15: =AVERAGE(E10:E14) -> 0.29226141 | J15: =COUNTIF(J10:J14,"<>ns")&" of 5 sig." -> 3 of 5 sig.
C16: SD | E16: =_xlfn.STDEV.S(E10:E14) -> 0.1231913
A17: Content words and pronouns | B17: Mirror | C17: Extraversion | D17: =COUNT('BFI Scores'!$Q$2:$Q$96) -> 95 | E17: =CORREL('BFI Scores'!$Q$2:$Q$96,'BFI Scores'!$B$2:$B$96) -> 0.44253637 | F17: =FISHERINV(FISHER(E17)-NORMSINV(0.975)/SQRT(D17-3)) -> 0.26459239 | G17: =FISHERINV(FISHER(E17)+NORMSINV(0.975)/SQRT(D17-3)) -> 0.59133788 | H17: =TDIST(ABS(E17)*SQRT((D17-2)/(1-E17^2)),D17-2,2) -> 7.1110894e-06 | I17: 2.13e-05 | J17: ***
A18: Content words and pronouns | B18: Mirror | C18: Agreeableness | D18: =COUNT('BFI Scores'!$R$2:$R$96) -> 95 | E18: =CORREL('BFI Scores'!$R$2:$R$96,'BFI Scores'!$C$2:$C$96) -> 0.21008992 | F18: =FISHERINV(FISHER(E18)-NORMSINV(0.975)/SQRT(D18-3)) -> 0.0089248121 | G18: =FISHERINV(FISHER(E18)+NORMSINV(0.975)/SQRT(D18-3)) -> 0.39491152 | H18: =TDIST(ABS(E18)*SQRT((D18-2)/(1-E18^2)),D18-2,2) -> 0.041006796 | I18: 0.041006796 | J18: *
A19: Content words and pronouns | B19: Mirror | C19: Conscientiousness | D19: =COUNT('BFI Scores'!$S$2:$S$96) -> 95 | E19: =CORREL('BFI Scores'!$S$2:$S$96,'BFI Scores'!$D$2:$D$96) -> 0.25264129 | F19: =FISHERINV(FISHER(E19)-NORMSINV(0.975)/SQRT(D19-3)) -> 0.053839699 | G19: =FISHERINV(FISHER(E19)+NORMSINV(0.975)/SQRT(D19-3)) -> 0.43217859 | H19: =TDIST(ABS(E19)*SQRT((D19-2)/(1-E19^2)),D19-2,2) -> 0.013509253 | I19: 0.027018506 | J19: *
A20: Content words and pronouns | B20: Mirror | C20: Neuroticism | D20: =COUNT('BFI Scores'!$T$2:$T$96) -> 95 | E20: =CORREL('BFI Scores'!$T$2:$T$96,'BFI Scores'!$E$2:$E$96) -> 0.60190232 | F20: =FISHERINV(FISHER(E20)-NORMSINV(0.975)/SQRT(D20-3)) -> 0.45563162 | G20: =FISHERINV(FISHER(E20)+NORMSINV(0.975)/SQRT(D20-3)) -> 0.71652433 | H20: =TDIST(ABS(E20)*SQRT((D20-2)/(1-E20^2)),D20-2,2) -> 1.1076111e-10 | I20: 5.54e-10 | J20: ***
A21: Content words and pronouns | B21: Mirror | C21: Openness | D21: =COUNT('BFI Scores'!$U$2:$U$96) -> 95 | E21: =CORREL('BFI Scores'!$U$2:$U$96,'BFI Scores'!$F$2:$F$96) -> 0.45169753 | F21: =FISHERINV(FISHER(E21)-NORMSINV(0.975)/SQRT(D21-3)) -> 0.27520854 | G21: =FISHERINV(FISHER(E21)+NORMSINV(0.975)/SQRT(D21-3)) -> 0.59873391 | H21: =TDIST(ABS(E21)*SQRT((D21-2)/(1-E21^2)),D21-2,2) -> 4.3355107e-06 | I21: 1.73e-05 | J21: ***
A22: Content words and pronouns | B22: Mirror | C22: Mean across traits | E22: =AVERAGE(E17:E21) -> 0.39177349 | J22: =COUNTIF(J17:J21,"<>ns")&" of 5 sig." -> 5 of 5 sig.
C23: SD | E23: =_xlfn.STDEV.S(E17:E21) -> 0.16022529
A24: Content words and pronouns | B24: Inverse | C24: Extraversion | D24: =COUNT('BFI Scores'!$V$2:$V$96) -> 95 | E24: =CORREL('BFI Scores'!$V$2:$V$96,'BFI Scores'!$B$2:$B$96) -> 0.039027128 | F24: =FISHERINV(FISHER(E24)-NORMSINV(0.975)/SQRT(D24-3)) -> -0.16380431 | G24: =FISHERINV(FISHER(E24)+NORMSINV(0.975)/SQRT(D24-3)) -> 0.23869266 | H24: =TDIST(ABS(E24)*SQRT((D24-2)/(1-E24^2)),D24-2,2) -> 0.70729102 | I24: 0.86215566 | J24: ns
A25: Content words and pronouns | B25: Inverse | C25: Agreeableness | D25: =COUNT('BFI Scores'!$W$2:$W$96) -> 95 | E25: =CORREL('BFI Scores'!$W$2:$W$96,'BFI Scores'!$C$2:$C$96) -> 0.089400667 | F25: =FISHERINV(FISHER(E25)-NORMSINV(0.975)/SQRT(D25-3)) -> -0.1142 | G25: =FISHERINV(FISHER(E25)+NORMSINV(0.975)/SQRT(D25-3)) -> 0.28579421 | H25: =TDIST(ABS(E25)*SQRT((D25-2)/(1-E25^2)),D25-2,2) -> 0.38892889 | I25: 0.86215566 | J25: ns
A26: Content words and pronouns | B26: Inverse | C26: Conscientiousness | D26: =COUNT('BFI Scores'!$X$2:$X$96) -> 95 | E26: =CORREL('BFI Scores'!$X$2:$X$96,'BFI Scores'!$D$2:$D$96) -> 0.11027786 | F26: =FISHERINV(FISHER(E26)-NORMSINV(0.975)/SQRT(D26-3)) -> -0.093339687 | G26: =FISHERINV(FISHER(E26)+NORMSINV(0.975)/SQRT(D26-3)) -> 0.30504111 | H26: =TDIST(ABS(E26)*SQRT((D26-2)/(1-E26^2)),D26-2,2) -> 0.28738522 | I26: 0.86215566 | J26: ns
A27: Content words and pronouns | B27: Inverse | C27: Neuroticism | D27: =COUNT('BFI Scores'!$Y$2:$Y$96) -> 95 | E27: =CORREL('BFI Scores'!$Y$2:$Y$96,'BFI Scores'!$E$2:$E$96) -> -0.24859562 | F27: =FISHERINV(FISHER(E27)-NORMSINV(0.975)/SQRT(D27-3)) -> -0.42866152 | G27: =FISHERINV(FISHER(E27)+NORMSINV(0.975)/SQRT(D27-3)) -> -0.049534418 | H27: =TDIST(ABS(E27)*SQRT((D27-2)/(1-E27^2)),D27-2,2) -> 0.015132236 | I27: 0.07566118 | J27: ns
A28: Content words and pronouns | B28: Inverse | C28: Openness | D28: =COUNT('BFI Scores'!$Z$2:$Z$96) -> 95 | E28: =CORREL('BFI Scores'!$Z$2:$Z$96,'BFI Scores'!$F$2:$F$96) -> 0.1518823 | F28: =FISHERINV(FISHER(E28)-NORMSINV(0.975)/SQRT(D28-3)) -> -0.051228867 | G28: =FISHERINV(FISHER(E28)+NORMSINV(0.975)/SQRT(D28-3)) -> 0.342928 | H28: =TDIST(ABS(E28)*SQRT((D28-2)/(1-E28^2)),D28-2,2) -> 0.14174959 | I28: 0.56699836 | J28: ns
A29: Content words and pronouns | B29: Inverse | C29: Mean across traits | E29: =AVERAGE(E24:E28) -> 0.028398468 | J29: =COUNTIF(J24:J28,"<>ns")&" of 5 sig." -> 0 of 5 sig.
C30: SD | E30: =_xlfn.STDEV.S(E24:E28) -> 0.16008783
A31: Participant messages only | B31: Mirror | C31: Extraversion | D31: =COUNT('BFI Scores'!$AA$2:$AA$96) -> 95 | E31: =CORREL('BFI Scores'!$AA$2:$AA$96,'BFI Scores'!$B$2:$B$96) -> 0.44568371 | F31: =FISHERINV(FISHER(E31)-NORMSINV(0.975)/SQRT(D31-3)) -> 0.26823474 | G31: =FISHERINV(FISHER(E31)+NORMSINV(0.975)/SQRT(D31-3)) -> 0.59388163 | H31: =TDIST(ABS(E31)*SQRT((D31-2)/(1-E31^2)),D31-2,2) -> 6.009077e-06 | I31: 2.4036308e-05 | J31: ***
A32: Participant messages only | B32: Mirror | C32: Agreeableness | D32: =COUNT('BFI Scores'!$AB$2:$AB$96) -> 95 | E32: =CORREL('BFI Scores'!$AB$2:$AB$96,'BFI Scores'!$C$2:$C$96) -> 0.30846924 | F32: =FISHERINV(FISHER(E32)-NORMSINV(0.975)/SQRT(D32-3)) -> 0.11401449 | G32: =FISHERINV(FISHER(E32)+NORMSINV(0.975)/SQRT(D32-3)) -> 0.48016074 | H32: =TDIST(ABS(E32)*SQRT((D32-2)/(1-E32^2)),D32-2,2) -> 0.0023554688 | I32: 0.0047109375 | J32: **
A33: Participant messages only | B33: Mirror | C33: Conscientiousness | D33: =COUNT('BFI Scores'!$AC$2:$AC$96) -> 95 | E33: =CORREL('BFI Scores'!$AC$2:$AC$96,'BFI Scores'!$D$2:$D$96) -> 0.15000578 | F33: =FISHERINV(FISHER(E33)-NORMSINV(0.975)/SQRT(D33-3)) -> -0.053143902 | G33: =FISHERINV(FISHER(E33)+NORMSINV(0.975)/SQRT(D33-3)) -> 0.34123244 | H33: =TDIST(ABS(E33)*SQRT((D33-2)/(1-E33^2)),D33-2,2) -> 0.14679552 | I33: 0.14679552 | J33: ns
A34: Participant messages only | B34: Mirror | C34: Neuroticism | D34: =COUNT('BFI Scores'!$AD$2:$AD$96) -> 95 | E34: =CORREL('BFI Scores'!$AD$2:$AD$96,'BFI Scores'!$E$2:$E$96) -> 0.59504824 | F34: =FISHERINV(FISHER(E34)-NORMSINV(0.975)/SQRT(D34-3)) -> 0.44712836 | G34: =FISHERINV(FISHER(E34)+NORMSINV(0.975)/SQRT(D34-3)) -> 0.71128803 | H34: =TDIST(ABS(E34)*SQRT((D34-2)/(1-E34^2)),D34-2,2) -> 2.0287768e-10 | I34: 1.0143884e-09 | J34: ***
A35: Participant messages only | B35: Mirror | C35: Openness | D35: =COUNT('BFI Scores'!$AE$2:$AE$96) -> 95 | E35: =CORREL('BFI Scores'!$AE$2:$AE$96,'BFI Scores'!$F$2:$F$96) -> 0.43397579 | F35: =FISHERINV(FISHER(E35)-NORMSINV(0.975)/SQRT(D35-3)) -> 0.25471102 | G35: =FISHERINV(FISHER(E35)+NORMSINV(0.975)/SQRT(D35-3)) -> 0.58440402 | H35: =TDIST(ABS(E35)*SQRT((D35-2)/(1-E35^2)),D35-2,2) -> 1.1148164e-05 | I35: 3.3444491e-05 | J35: ***
A36: Participant messages only | B36: Mirror | C36: Mean across traits | E36: =AVERAGE(E31:E35) -> 0.38663655 | J36: =COUNTIF(J31:J35,"<>ns")&" of 5 sig." -> 4 of 5 sig.
C37: SD | E37: =_xlfn.STDEV.S(E31:E35) -> 0.16678373
A38: Participant messages only | B38: Inverse | C38: Extraversion | D38: =COUNT('BFI Scores'!$AF$2:$AF$96) -> 95 | E38: =CORREL('BFI Scores'!$AF$2:$AF$96,'BFI Scores'!$B$2:$B$96) -> 0.45701879 | F38: =FISHERINV(FISHER(E38)-NORMSINV(0.975)/SQRT(D38-3)) -> 0.28139476 | G38: =FISHERINV(FISHER(E38)+NORMSINV(0.975)/SQRT(D38-3)) -> 0.60301841 | H38: =TDIST(ABS(E38)*SQRT((D38-2)/(1-E38^2)),D38-2,2) -> 3.2309852e-06 | I38: 1.6154926e-05 | J38: ***
A39: Participant messages only | B39: Inverse | C39: Agreeableness | D39: =COUNT('BFI Scores'!$AG$2:$AG$96) -> 95 | E39: =CORREL('BFI Scores'!$AG$2:$AG$96,'BFI Scores'!$C$2:$C$96) -> 0.24006871 | F39: =FISHERINV(FISHER(E39)-NORMSINV(0.975)/SQRT(D39-3)) -> 0.040484516 | G39: =FISHERINV(FISHER(E39)+NORMSINV(0.975)/SQRT(D39-3)) -> 0.42123082 | H39: =TDIST(ABS(E39)*SQRT((D39-2)/(1-E39^2)),D39-2,2) -> 0.019113837 | I39: 0.05734151 | J39: ns
A40: Participant messages only | B40: Inverse | C40: Conscientiousness | D40: =COUNT('BFI Scores'!$AH$2:$AH$96) -> 95 | E40: =CORREL('BFI Scores'!$AH$2:$AH$96,'BFI Scores'!$D$2:$D$96) -> 0.14211976 | F40: =FISHERINV(FISHER(E40)-NORMSINV(0.975)/SQRT(D40-3)) -> -0.061175515 | G40: =FISHERINV(FISHER(E40)+NORMSINV(0.975)/SQRT(D40-3)) -> 0.33409325 | H40: =TDIST(ABS(E40)*SQRT((D40-2)/(1-E40^2)),D40-2,2) -> 0.16948548 | I40: 0.16948548 | J40: ns
...

Sheet MSE by trait
A1: participant_ID | B1: mirror_26_turn_extraversion | C1: mirror_26_turn_agreeableness | D1: mirror_26_turn_conscientiousness | E1: mirror_26_turn_neuroticism | F1: mirror_26_turn_openness | G1: inverse_26_turn_extraversion | H1: inverse_26_turn_agreeableness | I1: inverse_26_turn_conscientiousness | J1: inverse_26_turn_neuroticism | K1: inverse_26_turn_openness | L1: mirror_content_words_pron_extraversion | M1: mirror_content_words_pron_agreeableness | N1: mirror_content_words_pron_conscientiousness | O1: mirror_content_words_pron_neuroticism | P1: mirror_content_words_pron_openness | Q1: inverse_content_words_pron_extraversion | R1: inverse_content_words_pron_agreeableness | S1: inverse_content_words_pron_conscientiousness | T1: inverse_content_words_pron_neuroticism | U1: inverse_content_words_pron_openness | V1: mirror_participant_only_extraversion | W1: mirror_participant_only_agreeableness | X1: mirror_participant_only_conscientiousness | Y1: mirror_participant_only_neuroticism | Z1: mirror_participant_only_openness | AA1: inverse_participant_only_extraversion | AB1: inverse_participant_only_agreeableness | AC1: inverse_participant_only_conscientiousness | AD1: inverse_participant_only_neuroticism | AE1: inverse_participant_only_openness | AF1: mean_mirror_26_turn | AG1: mean_inverse_26_turn | AH1: mean_mirror_content_words_pron | AI1: mean_inverse_content_words_pron | AJ1: mean_mirror_participant_only | AK1: mean_inverse_participant_only
A2: 10345 | B2: =('BFI Scores'!G2-'BFI Scores'!B2)^2 -> 0.765625 | C2: =('BFI Scores'!H2-'BFI Scores'!C2)^2 -> 0.0050567901 | D2: =('BFI Scores'!I2-'BFI Scores'!D2)^2 -> 4.0938778 | E2: =('BFI Scores'!J2-'BFI Scores'!E2)^2 -> 0.1225 | F2: =('BFI Scores'!K2-'BFI Scores'!F2)^2 -> 0.1764 | G2: =('BFI Scores'!L2-'BFI Scores'!B2)^2 -> 0.62015625 | H2: =('BFI Scores'!M2-'BFI Scores'!C2)^2 -> 0.2116 | I2: =('BFI Scores'!N2-'BFI Scores'!D2)^2 -> 2.286816 | J2: =('BFI Scores'!O2-'BFI Scores'!E2)^2 -> 0.05640625 | K2: =('BFI Scores'!P2-'BFI Scores'!F2)^2 -> 0.6724 | L2: =('BFI Scores'!Q2-'BFI Scores'!B2)^2 -> 0.180625 | M2: =('BFI Scores'!R2-'BFI Scores'!C2)^2 -> 0.056538272 | N2: =('BFI Scores'!S2-'BFI Scores'!D2)^2 -> 5.142816 | O2: =('BFI Scores'!T2-'BFI Scores'!E2)^2 -> 0.02640625 | P2: =('BFI Scores'!U2-'BFI Scores'!F2)^2 -> 0.0784 | Q2: =('BFI Scores'!V2-'BFI Scores'!B2)^2 -> 0.09765625 | R2: =('BFI Scores'!W2-'BFI Scores'!C2)^2 -> 1.1001679 | S2: =('BFI Scores'!X2-'BFI Scores'!D2)^2 -> 7.6605938 | T2: =('BFI Scores'!Y2-'BFI Scores'!E2)^2 -> 0.87890625 | U2: =('BFI Scores'!Z2-'BFI Scores'!F2)^2 -> 0.7744 | V2: =('BFI Scores'!AA2-'BFI Scores'!B2)^2 -> 0.62015625 | W2: =('BFI Scores'!AB2-'BFI Scores'!C2)^2 -> 0.013353086 | X2: =('BFI Scores'!AC2-'BFI Scores'!D2)^2 -> 7.0578778 | Y2: =('BFI Scores'!AD2-'BFI Scores'!E2)^2 -> 0.03515625 | Z2: =('BFI Scores'!AE2-'BFI Scores'!F2)^2 -> 0.01 | AA2: =('BFI Scores'!AF2-'BFI Scores'!B2)^2 -> 0.00015625 | AB2: =('BFI Scores'!AG2-'BFI Scores'!C2)^2 -> 0.5776 | AC2: =('BFI Scores'!AH2-'BFI Scores'!D2)^2 -> 5.5538778 | AD2: =('BFI Scores'!AI2-'BFI Scores'!E2)^2 -> 0.00765625 | AE2: =('BFI Scores'!AJ2-'BFI Scores'!F2)^2 -> 1.0201 | AF2: =AVERAGE(B2:F2) -> 1.0326919 | AG2: =AVERAGE(G2:K2) -> 0.76947571 | AH2: =AVERAGE(L2:P2) -> 1.0969571 | AI2: =AVERAGE(Q2:U2) -> 2.1023448 | AJ2: =AVERAGE(V2:Z2) -> 1.5473087 | AK2: =AVERAGE(AA2:AE2) -> 1.4318781
A3: 11492 | B3: =('BFI Scores'!G3-'BFI Scores'!B3)^2 -> 0.11390625 | C3: =('BFI Scores'!H3-'BFI Scores'!C3)^2 -> 0 | D3: =('BFI Scores'!I3-'BFI Scores'!D3)^2 -> 1.4667901 | E3: =('BFI Scores'!J3-'BFI Scores'!E3)^2 -> 0.01890625 | F3: =('BFI Scores'!K3-'BFI Scores'!F3)^2 -> 1.7689 | G3: =('BFI Scores'!L3-'BFI Scores'!B3)^2 -> 0.17015625 | H3: =('BFI Scores'!M3-'BFI Scores'!C3)^2 -> 0.83012346 | I3: =('BFI Scores'!N3-'BFI Scores'!D3)^2 -> 0.42975309 | J3: =('BFI Scores'!O3-'BFI Scores'!E3)^2 -> 0.030625 | K3: =('BFI Scores'!P3-'BFI Scores'!F3)^2 -> 2.89 | L3: =('BFI Scores'!Q3-'BFI Scores'!B3)^2 -> 0.0025 | M3: =('BFI Scores'!R3-'BFI Scores'!C3)^2 -> 0.19753086 | N3: =('BFI Scores'!S3-'BFI Scores'!D3)^2 -> 3.5679012 | O3: =('BFI Scores'!T3-'BFI Scores'!E3)^2 -> 1.96 | P3: =('BFI Scores'!U3-'BFI Scores'!F3)^2 -> 1.1025 | Q3: =('BFI Scores'!V3-'BFI Scores'!B3)^2 -> 0.9025 | R3: =('BFI Scores'!W3-'BFI Scores'!C3)^2 -> 1.185679 | S3: =('BFI Scores'!X3-'BFI Scores'!D3)^2 -> 1.3611111 | T3: =('BFI Scores'!Y3-'BFI Scores'!E3)^2 -> 5.4639062 | U3: =('BFI Scores'!Z3-'BFI Scores'!F3)^2 -> 2.7556 | V3: =('BFI Scores'!AA3-'BFI Scores'!B3)^2 -> 0.7225 | W3: =('BFI Scores'!AB3-'BFI Scores'!C3)^2 -> 0.00049382716 | X3: =('BFI Scores'!AC3-'BFI Scores'!D3)^2 -> 3.3611111 | Y3: =('BFI Scores'!AD3-'BFI Scores'!E3)^2 -> 0.030625 | Z3: =('BFI Scores'!AE3-'BFI Scores'!F3)^2 -> 2.2801 | AA3: =('BFI Scores'!AF3-'BFI Scores'!B3)^2 -> 0.00015625 | AB3: =('BFI Scores'!AG3-'BFI Scores'!C3)^2 -> 0.97790123 | AC3: =('BFI Scores'!AH3-'BFI Scores'!D3)^2 -> 2.022716 | AD3: =('BFI Scores'!AI3-'BFI Scores'!E3)^2 -> 0.01265625 | AE3: =('BFI Scores'!AJ3-'BFI Scores'!F3)^2 -> 3.4596 | AF3: =AVERAGE(B3:F3) -> 0.67370052 | AG3: =AVERAGE(G3:K3) -> 0.87013156 | AH3: =AVERAGE(L3:P3) -> 1.3660864 | AI3: =AVERAGE(Q3:U3) -> 2.3337593 | AJ3: =AVERAGE(V3:Z3) -> 1.278966 | AK3: =AVERAGE(AA3:AE3) -> 1.294606
A4: 12178 | B4: =('BFI Scores'!G4-'BFI Scores'!B4)^2 -> 2.2126562 | C4: =('BFI Scores'!H4-'BFI Scores'!C4)^2 -> 0.0484 | D4: =('BFI Scores'!I4-'BFI Scores'!D4)^2 -> 3.1604938 | E4: =('BFI Scores'!J4-'BFI Scores'!E4)^2 -> 0.011025 | F4: =('BFI Scores'!K4-'BFI Scores'!F4)^2 -> 0.4489 | G4: =('BFI Scores'!L4-'BFI Scores'!B4)^2 -> 0.525625 | H4: =('BFI Scores'!M4-'BFI Scores'!C4)^2 -> 0.37074568 | I4: =('BFI Scores'!N4-'BFI Scores'!D4)^2 -> 0.15123457 | J4: =('BFI Scores'!O4-'BFI Scores'!E4)^2 -> 0.17430625 | K4: =('BFI Scores'!P4-'BFI Scores'!F4)^2 -> 0.7225 | L4: =('BFI Scores'!Q4-'BFI Scores'!B4)^2 -> 5.5225 | M4: =('BFI Scores'!R4-'BFI Scores'!C4)^2 -> 3.859042 | N4: =('BFI Scores'!S4-'BFI Scores'!D4)^2 -> 5.0875309 | O4: =('BFI Scores'!T4-'BFI Scores'!E4)^2 -> 2.6244 | P4: =('BFI Scores'!U4-'BFI Scores'!F4)^2 -> 1.0404 | Q4: =('BFI Scores'!V4-'BFI Scores'!B4)^2 -> 3.5626563 | R4: =('BFI Scores'!W4-'BFI Scores'!C4)^2 -> 4.2619309 | S4: =('BFI Scores'!X4-'BFI Scores'!D4)^2 -> 1.8075309 | T4: =('BFI Scores'!Y4-'BFI Scores'!E4)^2 -> 0.61230625 | U4: =('BFI Scores'!Z4-'BFI Scores'!F4)^2 -> 1.21 | V4: =('BFI Scores'!AA4-'BFI Scores'!B4)^2 -> 2.640625 | W4: =('BFI Scores'!AB4-'BFI Scores'!C4)^2 -> 0.12484444 | X4: =('BFI Scores'!AC4-'BFI Scores'!D4)^2 -> 4.9877778 | Y4: =('BFI Scores'!AD4-'BFI Scores'!E4)^2 -> 0.36905625 | Z4: =('BFI Scores'!AE4-'BFI Scores'!F4)^2 -> 0.5329 | AA4: =('BFI Scores'!AF4-'BFI Scores'!B4)^2 -> 1.5314062 | AB4: =('BFI Scores'!AG4-'BFI Scores'!C4)^2 -> 1.0862272 | AC4: =('BFI Scores'!AH4-'BFI Scores'!D4)^2 -> 0.50567901 | AD4: =('BFI Scores'!AI4-'BFI Scores'!E4)^2 -> 0.003025 | AE4: =('BFI Scores'!AJ4-'BFI Scores'!F4)^2 -> 0.2401 | AF4: =AVERAGE(B4:F4) -> 1.176295 | AG4: =AVERAGE(G4:K4) -> 0.3888823 | AH4: =AVERAGE(L4:P4) -> 3.6267746 | AI4: =AVERAGE(Q4:U4) -> 2.2908848 | AJ4: =AVERAGE(V4:Z4) -> 1.7310407 | AK4: =AVERAGE(AA4:AE4) -> 0.67328748
A5: 16042 | B5: =('BFI Scores'!G5-'BFI Scores'!B5)^2 -> 0.893025 | C5: =('BFI Scores'!H5-'BFI Scores'!C5)^2 -> 0.0083012346 | D5: =('BFI Scores'!I5-'BFI Scores'!D5)^2 -> 0.57254444 | E5: =('BFI Scores'!J5-'BFI Scores'!E5)^2 -> 0.11730625 | F5: =('BFI Scores'!K5-'BFI Scores'!F5)^2 -> 0.1296 | G5: =('BFI Scores'!L5-'BFI Scores'!B5)^2 -> 0.09455625 | H5: =('BFI Scores'!M5-'BFI Scores'!C5)^2 -> 0.072301235 | I5: =('BFI Scores'!N5-'BFI Scores'!D5)^2 -> 1.1881 | J5: =('BFI Scores'!O5-'BFI Scores'!E5)^2 -> 0.01155625 | K5: =('BFI Scores'!P5-'BFI Scores'!F5)^2 -> 0.0441 | L5: =('BFI Scores'!Q5-'BFI Scores'!B5)^2 -> 1.3689 | M5: =('BFI Scores'!R5-'BFI Scores'!C5)^2 -> 0.1529679 | N5: =('BFI Scores'!S5-'BFI Scores'!D5)^2 -> 0.7921 | O5: =('BFI Scores'!T5-'BFI Scores'!E5)^2 -> 2.5e-05 | P5: =('BFI Scores'!U5-'BFI Scores'!F5)^2 -> 0.3721 | Q5: =('BFI Scores'!V5-'BFI Scores'!B5)^2 -> 0.1369 | R5: =('BFI Scores'!W5-'BFI Scores'!C5)^2 -> 1.5820049 | S5: =('BFI Scores'!X5-'BFI Scores'!D5)^2 -> 7.5380753 | T5: =('BFI Scores'!Y5-'BFI Scores'!E5)^2 -> 1.311025 | U5: =('BFI Scores'!Z5-'BFI Scores'!F5)^2 -> 0.5329 | V5: =('BFI Scores'!AA5-'BFI Scores'!B5)^2 -> 1.550025 | W5: =('BFI Scores'!AB5-'BFI Scores'!C5)^2 -> 0.00096790123 | X5: =('BFI Scores'!AC5-'BFI Scores'!D5)^2 -> 0.6066679 | Y5: =('BFI Scores'!AD5-'BFI Scores'!E5)^2 -> 0.1444 | Z5: =('BFI Scores'!AE5-'BFI Scores'!F5)^2 -> 0.1225 | AA5: =('BFI Scores'!AF5-'BFI Scores'!B5)^2 -> 0.73530625 | AB5: =('BFI Scores'!AG5-'BFI Scores'!C5)^2 -> 0.12800494 | AC5: =('BFI Scores'!AH5-'BFI Scores'!D5)^2 -> 3.1250383 | AD5: =('BFI Scores'!AI5-'BFI Scores'!E5)^2 -> 0.0144 | AE5: =('BFI Scores'!AJ5-'BFI Scores'!F5)^2 -> 0.0529 | AF5: =AVERAGE(B5:F5) -> 0.34415539 | AG5: =AVERAGE(G5:K5) -> 0.28212275 | AH5: =AVERAGE(L5:P5) -> 0.53721858 | AI5: =AVERAGE(Q5:U5) -> 2.220181 | AJ5: =AVERAGE(V5:Z5) -> 0.48491216 | AK5: =AVERAGE(AA5:AE5) -> 0.81112989
A6: 16234 | B6: =('BFI Scores'!G6-'BFI Scores'!B6)^2 -> 0.31080625 | C6: =('BFI Scores'!H6-'BFI Scores'!C6)^2 -> 2.6714086 | D6: =('BFI Scores'!I6-'BFI Scores'!D6)^2 -> 0.66513086 | E6: =('BFI Scores'!J6-'BFI Scores'!E6)^2 -> 7.9101562 | F6: =('BFI Scores'!K6-'BFI Scores'!F6)^2 -> 2.2201 | G6: =('BFI Scores'!L6-'BFI Scores'!B6)^2 -> 0.297025 | H6: =('BFI Scores'!M6-'BFI Scores'!C6)^2 -> 2.7078531 | I6: =('BFI Scores'!N6-'BFI Scores'!D6)^2 -> 0.77831605 | J6: =('BFI Scores'!O6-'BFI Scores'!E6)^2 -> 7.9101562 | K6: =('BFI Scores'!P6-'BFI Scores'!F6)^2 -> 0.5184 | L6: =('BFI Scores'!Q6-'BFI Scores'!B6)^2 -> 1.3398063 | M6: =('BFI Scores'!R6-'BFI Scores'!C6)^2 -> 1.7219272 | N6: =('BFI Scores'!S6-'BFI Scores'!D6)^2 -> 0.36535309 | O6: =('BFI Scores'!T6-'BFI Scores'!E6)^2 -> 4.41 | P6: =('BFI Scores'!U6-'BFI Scores'!F6)^2 -> 2.0449 | Q6: =('BFI Scores'!V6-'BFI Scores'!B6)^2 -> 2.5840562 | R6: =('BFI Scores'!W6-'BFI Scores'!C6)^2 -> 4.1389642 | S6: =('BFI Scores'!X6-'BFI Scores'!D6)^2 -> 2.3647605 | T6: =('BFI Scores'!Y6-'BFI Scores'!E6)^2 -> 12.075625 | U6: =('BFI Scores'!Z6-'BFI Scores'!F6)^2 -> 1.1664 | V6: =('BFI Scores'!AA6-'BFI Scores'!B6)^2 -> 0.82355625 | W6: =('BFI Scores'!AB6-'BFI Scores'!C6)^2 -> 2.1543716 | X6: =('BFI Scores'!AC6-'BFI Scores'!D6)^2 -> 1.1953778 | Y6: =('BFI Scores'!AD6-'BFI Scores'!E6)^2 -> 7.0225 | Z6: =('BFI Scores'!AE6-'BFI Scores'!F6)^2 -> 1.96 | AA6: =('BFI Scores'!AF6-'BFI Scores'!B6)^2 -> 2.0520563 | AB6: =('BFI Scores'!AG6-'BFI Scores'!C6)^2 -> 3.6992111 | AC6: =('BFI Scores'!AH6-'BFI Scores'!D6)^2 -> 2.3990568 | AD6: =('BFI Scores'!AI6-'BFI Scores'!E6)^2 -> 10.643906 | AE6: =('BFI Scores'!AJ6-'BFI Scores'!F6)^2 -> 0.3969 | AF6: =AVERAGE(B6:F6) -> 2.7555204 | AG6: =AVERAGE(G6:K6) -> 2.4423501 | AH6: =AVERAGE(L6:P6) -> 1.9763973 | AI6: =AVERAGE(Q6:U6) -> 4.4659612 | AJ6: =AVERAGE(V6:Z6) -> 2.6311611 | AK6: =AVERAGE(AA6:AE6) -> 3.8382261
A7: 17304 | B7: =('BFI Scores'!G7-'BFI Scores'!B7)^2 -> 0.105625 | C7: =('BFI Scores'!H7-'BFI Scores'!C7)^2 -> 0.036949383 | D7: =('BFI Scores'!I7-'BFI Scores'!D7)^2 -> 5.5068444 | E7: =('BFI Scores'!J7-'BFI Scores'!E7)^2 -> 0.0009 | F7: =('BFI Scores'!K7-'BFI Scores'!F7)^2 -> 1.44 | G7: =('BFI Scores'!L7-'BFI Scores'!B7)^2 -> 0.25 | H7: =('BFI Scores'!M7-'BFI Scores'!C7)^2 -> 0.014134568 | I7: =('BFI Scores'!N7-'BFI Scores'!D7)^2 -> 0.021511111 | J7: =('BFI Scores'!O7-'BFI Scores'!E7)^2 -> 0.003025 | K7: =('BFI Scores'!P7-'BFI Scores'!F7)^2 -> 1.8769 | L7: =('BFI Scores'!Q7-'BFI Scores'!B7)^2 -> 0.01265625 | M7: =('BFI Scores'!R7-'BFI Scores'!C7)^2 -> 0.4489 | N7: =('BFI Scores'!S7-'BFI Scores'!D7)^2 -> 6.5991901 | O7: =('BFI Scores'!T7-'BFI Scores'!E7)^2 -> 0.20930625 | P7: =('BFI Scores'!U7-'BFI Scores'!F7)^2 -> 2.9584 | Q7: =('BFI Scores'!V7-'BFI Scores'!B7)^2 -> 0.87890625 | R7: =('BFI Scores'!W7-'BFI Scores'!C7)^2 -> 0.0729 | S7: =('BFI Scores'!X7-'BFI Scores'!D7)^2 -> 3.8328938 | T7: =('BFI Scores'!Y7-'BFI Scores'!E7)^2 -> 5.625e-05 | U7: =('BFI Scores'!Z7-'BFI Scores'!F7)^2 -> 3.0276 | V7: =('BFI Scores'!AA7-'BFI Scores'!B7)^2 -> 0.050625 | W7: =('BFI Scores'!AB7-'BFI Scores'!C7)^2 -> 0.20050494 | X7: =('BFI Scores'!AC7-'BFI Scores'!D7)^2 -> 6.7715605 | Y7: =('BFI Scores'!AD7-'BFI Scores'!E7)^2 -> 0.40005625 | Z7: =('BFI Scores'!AE7-'BFI Scores'!F7)^2 -> 1.1664 | AA7: =('BFI Scores'!AF7-'BFI Scores'!B7)^2 -> 1.050625 | AB7: =('BFI Scores'!AG7-'BFI Scores'!C7)^2 -> 0.18109753 | AC7: =('BFI Scores'!AH7-'BFI Scores'!D7)^2 -> 0.4326716 | AD7: =('BFI Scores'!AI7-'BFI Scores'!E7)^2 -> 0.04730625 | AE7: =('BFI Scores'!AJ7-'BFI Scores'!F7)^2 -> 2.3409 | AF7: =AVERAGE(B7:F7) -> 1.4180638 | AG7: =AVERAGE(G7:K7) -> 0.43311414 | AH7: =AVERAGE(L7:P7) -> 2.0456905 | AI7: =AVERAGE(Q7:U7) -> 1.5624713 | AJ7: =AVERAGE(V7:Z7) -> 1.7178293 | AK7: =AVERAGE(AA7:AE7) -> 0.81052008
A8: 18724 | B8: =('BFI Scores'!G8-'BFI Scores'!B8)^2 -> 5.625e-05 | C8: =('BFI Scores'!H8-'BFI Scores'!C8)^2 -> 0.32111111 | D8: =('BFI Scores'!I8-'BFI Scores'!D8)^2 -> 0.67787778 | E8: =('BFI Scores'!J8-'BFI Scores'!E8)^2 -> 2.3409 | F8: =('BFI Scores'!K8-'BFI Scores'!F8)^2 -> 0.9801 | G8: =('BFI Scores'!L8-'BFI Scores'!B8)^2 -> 0.024025 | H8: =('BFI Scores'!M8-'BFI Scores'!C8)^2 -> 0.65790123 | I8: =('BFI Scores'!N8-'BFI Scores'!D8)^2 -> 0.0032111111 | J8: =('BFI Scores'!O8-'BFI Scores'!E8)^2 -> 2.0449 | K8: =('BFI Scores'!P8-'BFI Scores'!F8)^2 -> 0.3136 | L8: =('BFI Scores'!Q8-'BFI Scores'!B8)^2 -> 1.8769 | M8: =('BFI Scores'!R8-'BFI Scores'!C8)^2 -> 1.0223457 | N8: =('BFI Scores'!S8-'BFI Scores'!D8)^2 -> 0.6066679 | O8: =('BFI Scores'!T8-'BFI Scores'!E8)^2 -> 2.1904 | P8: =('BFI Scores'!U8-'BFI Scores'!F8)^2 -> 0.0144 | Q8: =('BFI Scores'!V8-'BFI Scores'!B8)^2 -> 0.3844 | R8: =('BFI Scores'!W8-'BFI Scores'!C8)^2 -> 0.38716049 | S8: =('BFI Scores'!X8-'BFI Scores'!D8)^2 -> 0.75303827 | T8: =('BFI Scores'!Y8-'BFI Scores'!E8)^2 -> 0.26780625 | U8: =('BFI Scores'!Z8-'BFI Scores'!F8)^2 -> 0.09 | V8: =('BFI Scores'!AA8-'BFI Scores'!B8)^2 -> 0.31080625 | W8: =('BFI Scores'!AB8-'BFI Scores'!C8)^2 -> 0.60493827 | X8: =('BFI Scores'!AC8-'BFI Scores'!D8)^2 -> 0.85254444 | Y8: =('BFI Scores'!AD8-'BFI Scores'!E8)^2 -> 1.9390562 | Z8: =('BFI Scores'!AE8-'BFI Scores'!F8)^2 -> 0.8281 | AA8: =('BFI Scores'!AF8-'BFI Scores'!B8)^2 -> 2.5e-05 | AB8: =('BFI Scores'!AG8-'BFI Scores'!C8)^2 -> 0.60493827 | AC8: =('BFI Scores'!AH8-'BFI Scores'!D8)^2 -> 0.75303827 | AD8: =('BFI Scores'!AI8-'BFI Scores'!E8)^2 -> 1.9044 | AE8: =('BFI Scores'!AJ8-'BFI Scores'!F8)^2 -> 0.4761 | AF8: =AVERAGE(B8:F8) -> 0.86400903 | AG8: =AVERAGE(G8:K8) -> 0.60872747 | AH8: =AVERAGE(L8:P8) -> 1.1421427 | AI8: =AVERAGE(Q8:U8) -> 0.376481 | AJ8: =AVERAGE(V8:Z8) -> 0.90708904 | AK8: =AVERAGE(AA8:AE8) -> 0.74770031
A9: 21566 | B9: =('BFI Scores'!G9-'BFI Scores'!B9)^2 -> 0.4489 | C9: =('BFI Scores'!H9-'BFI Scores'!C9)^2 -> 0.0144 | D9: =('BFI Scores'!I9-'BFI Scores'!D9)^2 -> 0.82607901 | E9: =('BFI Scores'!J9-'BFI Scores'!E9)^2 -> 1.1289062 | F9: =('BFI Scores'!K9-'BFI Scores'!F9)^2 -> 0.6084 | G9: =('BFI Scores'!L9-'BFI Scores'!B9)^2 -> 0.5184 | H9: =('BFI Scores'!M9-'BFI Scores'!C9)^2 -> 0.095412346 | I9: =('BFI Scores'!N9-'BFI Scores'!D9)^2 -> 0.02022716 | J9: =('BFI Scores'!O9-'BFI Scores'!E9)^2 -> 0.70140625 | K9: =('BFI Scores'!P9-'BFI Scores'!F9)^2 -> 0.04 | L9: =('BFI Scores'!Q9-'BFI Scores'!B9)^2 -> 2.387025 | M9: =('BFI Scores'!R9-'BFI Scores'!C9)^2 -> 0.44741235 | N9: =('BFI Scores'!S9-'BFI Scores'!D9)^2 -> 1.5156346 | O9: =('BFI Scores'!T9-'BFI Scores'!E9)^2 -> 0.140625 | P9: =('BFI Scores'!U9-'BFI Scores'!F9)^2 -> 2.4649 | Q9: =('BFI Scores'!V9-'BFI Scores'!B9)^2 -> 3.6864 | R9: =('BFI Scores'!W9-'BFI Scores'!C9)^2 -> 0.3312642 | S9: =('BFI Scores'!X9-'BFI Scores'!D9)^2 -> 0.65430123 | T9: =('BFI Scores'!Y9-'BFI Scores'!E9)^2 -> 2.3639063 | U9: =('BFI Scores'!Z9-'BFI Scores'!F9)^2 -> 0.0081 | V9: =('BFI Scores'!AA9-'BFI Scores'!B9)^2 -> 1.8428062 | W9: =('BFI Scores'!AB9-'BFI Scores'!C9)^2 -> 0.010449383 | X9: =('BFI Scores'!AC9-'BFI Scores'!D9)^2 -> 1.205116 | Y9: =('BFI Scores'!AD9-'BFI Scores'!E9)^2 -> 0.97515625 | Z9: =('BFI Scores'!AE9-'BFI Scores'!F9)^2 -> 0.81 | AA9: =('BFI Scores'!AF9-'BFI Scores'!B9)^2 -> 1.6448063 | AB9: =('BFI Scores'!AG9-'BFI Scores'!C9)^2 -> 0.3312642 | AC9: =('BFI Scores'!AH9-'BFI Scores'!D9)^2 -> 1.0631901 | AD9: =('BFI Scores'!AI9-'BFI Scores'!E9)^2 -> 0.330625 | AE9: =('BFI Scores'!AJ9-'BFI Scores'!F9)^2 -> 0.0004 | AF9: =AVERAGE(B9:F9) -> 0.60533705 | AG9: =AVERAGE(G9:K9) -> 0.27508915 | AH9: =AVERAGE(L9:P9) -> 1.3911194 | AI9: =AVERAGE(Q9:U9) -> 1.4087943 | AJ9: =AVERAGE(V9:Z9) -> 0.96870559 | AK9: =AVERAGE(AA9:AE9) -> 0.67405711
A10: 23105 | B10: =('BFI Scores'!G10-'BFI Scores'!B10)^2 -> 3.980025 | C10: =('BFI Scores'!H10-'BFI Scores'!C10)^2 -> 1.0290975 | D10: =('BFI Scores'!I10-'BFI Scores'!D10)^2 -> 0.40676049 | E10: =('BFI Scores'!J10-'BFI Scores'!E10)^2 -> 0.1089 | F10: =('BFI Scores'!K10-'BFI Scores'!F10)^2 -> 0.0001 | G10: =('BFI Scores'!L10-'BFI Scores'!B10)^2 -> 4.4415562 | H10: =('BFI Scores'!M10-'BFI Scores'!C10)^2 -> 0.57591235 | I10: =('BFI Scores'!N10-'BFI Scores'!D10)^2 -> 2.099279 | J10: =('BFI Scores'!O10-'BFI Scores'!E10)^2 -> 2.1904 | K10: =('BFI Scores'!P10-'BFI Scores'!F10)^2 -> 0.0676 | L10: =('BFI Scores'!Q10-'BFI Scores'!B10)^2 -> 3.2670563 | M10: =('BFI Scores'!R10-'BFI Scores'!C10)^2 -> 0.00035679012 | N10: =('BFI Scores'!S10-'BFI Scores'!D10)^2 -> 2.6100198 | O10: =('BFI Scores'!T10-'BFI Scores'!E10)^2 -> 0.1369 | P10: =('BFI Scores'!U10-'BFI Scores'!F10)^2 -> 0.0121 | Q10: =('BFI Scores'!V10-'BFI Scores'!B10)^2 -> 3.980025 | R10: =('BFI Scores'!W10-'BFI Scores'!C10)^2 -> 0.21057901 | S10: =('BFI Scores'!X10-'BFI Scores'!D10)^2 -> 3.2560198 | T10: =('BFI Scores'!Y10-'BFI Scores'!E10)^2 -> 0.11730625 | U10: =('BFI Scores'!Z10-'BFI Scores'!F10)^2 -> 0.8281 | V10: =('BFI Scores'!AA10-'BFI Scores'!B10)^2 -> 3.980025 | W10: =('BFI Scores'!AB10-'BFI Scores'!C10)^2 -> 1.0746778 | X10: =('BFI Scores'!AC10-'BFI Scores'!D10)^2 -> 0.4356 | Y10: =('BFI Scores'!AD10-'BFI Scores'!E10)^2 -> 0.0169 | Z10: =('BFI Scores'!AE10-'BFI Scores'!F10)^2 -> 0.0001 | AA10: =('BFI Scores'!AF10-'BFI Scores'!B10)^2 -> 4.4944 | AB10: =('BFI Scores'!AG10-'BFI Scores'!C10)^2 -> 0.68154198 | AC10: =('BFI Scores'!AH10-'BFI Scores'!D10)^2 -> 2.1316 | AD10: =('BFI Scores'!AI10-'BFI Scores'!E10)^2 -> 1.6705562 | AE10: =('BFI Scores'!AJ10-'BFI Scores'!F10)^2 -> 0.1849 | AF10: =AVERAGE(B10:F10) -> 1.1049766 | AG10: =AVERAGE(G10:K10) -> 1.8749495 | AH10: =AVERAGE(L10:P10) -> 1.2052866 | AI10: =AVERAGE(Q10:U10) -> 1.678406 | AJ10: =AVERAGE(V10:Z10) -> 1.1014606 | AK10: =AVERAGE(AA10:AE10) -> 1.8325996
A11: 23429 | B11: =('BFI Scores'!G11-'BFI Scores'!B11)^2 -> 0.10080625 | C11: =('BFI Scores'!H11-'BFI Scores'!C11)^2 -> 0.0676 | D11: =('BFI Scores'!I11-'BFI Scores'!D11)^2 -> 0.12641975 | E11: =('BFI Scores'!J11-'BFI Scores'!E11)^2 -> 0.25 | F11: =('BFI Scores'!K11-'BFI Scores'!F11)^2 -> 2.3104 | G11: =('BFI Scores'!L11-'BFI Scores'!B11)^2 -> 0.03330625 | H11: =('BFI Scores'!M11-'BFI Scores'!C11)^2 -> 0.022834568 | I11: =('BFI Scores'!N11-'BFI Scores'!D11)^2 -> 0.0060493827 | J11: =('BFI Scores'!O11-'BFI Scores'!E11)^2 -> 0.17015625 | K11: =('BFI Scores'!P11-'BFI Scores'!F11)^2 -> 2.7556 | L11: =('BFI Scores'!Q11-'BFI Scores'!B11)^2 -> 0.0049 | M11: =('BFI Scores'!R11-'BFI Scores'!C11)^2 -> 0.0053777778 | N11: =('BFI Scores'!S11-'BFI Scores'!D11)^2 -> 0.28444444 | O11: =('BFI Scores'!T11-'BFI Scores'!E11)^2 -> 3.515625 | P11: =('BFI Scores'!U11-'BFI Scores'!F11)^2 -> 0.8281 | Q11: =('BFI Scores'!V11-'BFI Scores'!B11)^2 -> 0.17430625 | R11: =('BFI Scores'!W11-'BFI Scores'!C11)^2 -> 0.0196 | S11: =('BFI Scores'!X11-'BFI Scores'!D11)^2 -> 0.41530864 | T11: =('BFI Scores'!Y11-'BFI Scores'!E11)^2 -> 5.76 | U11: =('BFI Scores'!Z11-'BFI Scores'!F11)^2 -> 2.3409 | V11: =('BFI Scores'!AA11-'BFI Scores'!B11)^2 -> 0.1764 | W11: =('BFI Scores'!AB11-'BFI Scores'!C11)^2 -> 0.20150123 | X11: =('BFI Scores'!AC11-'BFI Scores'!D11)^2 -> 0.30864198 | Y11: =('BFI Scores'!AD11-'BFI Scores'!E11)^2 -> 0.2025 | Z11: =('BFI Scores'!AE11-'BFI Scores'!F11)^2 -> 1.2769 | AA11: =('BFI Scores'!AF11-'BFI Scores'!B11)^2 -> 2.1978062 | AB11: =('BFI Scores'!AG11-'BFI Scores'!C11)^2 -> 1.4293531 | AC11: =('BFI Scores'!AH11-'BFI Scores'!D11)^2 -> 0 | AD11: =('BFI Scores'!AI11-'BFI Scores'!E11)^2 -> 0.2025 | AE11: =('BFI Scores'!AJ11-'BFI Scores'!F11)^2 -> 3.5721 | AF11: =AVERAGE(B11:F11) -> 0.5710452 | AG11: =AVERAGE(G11:K11) -> 0.59758929 | AH11: =AVERAGE(L11:P11) -> 0.92768944 | AI11: =AVERAGE(Q11:U11) -> 1.742023 | AJ11: =AVERAGE(V11:Z11) -> 0.43318864 | AK11: =AVERAGE(AA11:AE11) -> 1.4803519
A12: 23564 | B12: =('BFI Scores'!G12-'BFI Scores'!B12)^2 -> 0.065025 | C12: =('BFI Scores'!H12-'BFI Scores'!C12)^2 -> 0.8649 | D12: =('BFI Scores'!I12-'BFI Scores'!D12)^2 -> 6.3280198 | E12: =('BFI Scores'!J12-'BFI Scores'!E12)^2 -> 0.680625 | F12: =('BFI Scores'!K12-'BFI Scores'!F12)^2 -> 4.6225 | G12: =('BFI Scores'!L12-'BFI Scores'!B12)^2 -> 0.1444 | H12: =('BFI Scores'!M12-'BFI Scores'!C12)^2 -> 0.82406049 | I12: =('BFI Scores'!N12-'BFI Scores'!D12)^2 -> 0.54431605 | J12: =('BFI Scores'!O12-'BFI Scores'!E12)^2 -> 7.7701562 | K12: =('BFI Scores'!P12-'BFI Scores'!F12)^2 -> 4.41 | L12: =('BFI Scores'!Q12-'BFI Scores'!B12)^2 -> 0.57380625 | M12: =('BFI Scores'!R12-'BFI Scores'!C12)^2 -> 0.0055419753 | N12: =('BFI Scores'!S12-'BFI Scores'!D12)^2 -> 4.8107111 | O12: =('BFI Scores'!T12-'BFI Scores'!E12)^2 -> 0.01890625 | P12: =('BFI Scores'!U12-'BFI Scores'!F12)^2 -> 4.5796 | Q12: =('BFI Scores'!V12-'BFI Scores'!B12)^2 -> 0.024025 | R12: =('BFI Scores'!W12-'BFI Scores'!C12)^2 -> 1.798579 | S12: =('BFI Scores'!X12-'BFI Scores'!D12)^2 -> 4.2895012 | T12: =('BFI Scores'!Y12-'BFI Scores'!E12)^2 -> 10.481406 | U12: =('BFI Scores'!Z12-'BFI Scores'!F12)^2 -> 3.8025 | V12: =('BFI Scores'!AA12-'BFI Scores'!B12)^2 -> 0.09455625 | W12: =('BFI Scores'!AB12-'BFI Scores'!C12)^2 -> 0.31734444 | X12: =('BFI Scores'!AC12-'BFI Scores'!D12)^2 -> 6.5536 | Y12: =('BFI Scores'!AD12-'BFI Scores'!E12)^2 -> 0.855625 | Z12: =('BFI Scores'!AE12-'BFI Scores'!F12)^2 -> 4.1209 | AA12: =('BFI Scores'!AF12-'BFI Scores'!B12)^2 -> 0.1444 | AB12: =('BFI Scores'!AG12-'BFI Scores'!C12)^2 -> 0.88569012 | AC12: =('BFI Scores'!AH12-'BFI Scores'!D12)^2 -> 1.2444642 | AD12: =('BFI Scores'!AI12-'BFI Scores'!E12)^2 -> 8.265625 | AE12: =('BFI Scores'!AJ12-'BFI Scores'!F12)^2 -> 4.3264 | AF12: =AVERAGE(B12:F12) -> 2.512214 | AG12: =AVERAGE(G12:K12) -> 2.7385866 | AH12: =AVERAGE(L12:P12) -> 1.9977131 | AI12: =AVERAGE(Q12:U12) -> 4.0792023 | AJ12: =AVERAGE(V12:Z12) -> 2.3884051 | AK12: =AVERAGE(AA12:AE12) -> 2.9733159
A13: 24311 | B13: =('BFI Scores'!G13-'BFI Scores'!B13)^2 -> 0.25755625 | C13: =('BFI Scores'!H13-'BFI Scores'!C13)^2 -> 0.05548642 | D13: =('BFI Scores'!I13-'BFI Scores'!D13)^2 -> 6.0493827e-05 | E13: =('BFI Scores'!J13-'BFI Scores'!E13)^2 -> 0.0049 | F13: =('BFI Scores'!K13-'BFI Scores'!F13)^2 -> 0.0576 | G13: =('BFI Scores'!L13-'BFI Scores'!B13)^2 -> 0.990025 | H13: =('BFI Scores'!M13-'BFI Scores'!C13)^2 -> 0.0784 | I13: =('BFI Scores'!N13-'BFI Scores'!D13)^2 -> 1.4856901 | J13: =('BFI Scores'!O13-'BFI Scores'!E13)^2 -> 5.085025 | K13: =('BFI Scores'!P13-'BFI Scores'!F13)^2 -> 1.5876 | L13: =('BFI Scores'!Q13-'BFI Scores'!B13)^2 -> 5.3245563 | M13: =('BFI Scores'!R13-'BFI Scores'!C13)^2 -> 0.21570864 | N13: =('BFI Scores'!S13-'BFI Scores'!D13)^2 -> 0.36939383 | O13: =('BFI Scores'!T13-'BFI Scores'!E13)^2 -> 0.497025 | P13: =('BFI Scores'!U13-'BFI Scores'!F13)^2 -> 0.2916 | Q13: =('BFI Scores'!V13-'BFI Scores'!B13)^2 -> 2.8308063 | R13: =('BFI Scores'!W13-'BFI Scores'!C13)^2 -> 0.19556049 | S13: =('BFI Scores'!X13-'BFI Scores'!D13)^2 -> 0.84435679 | T13: =('BFI Scores'!Y13-'BFI Scores'!E13)^2 -> 2.2275562 | U13: =('BFI Scores'!Z13-'BFI Scores'!F13)^2 -> 1.5876 | V13: =('BFI Scores'!AA13-'BFI Scores'!B13)^2 -> 0.6724 | W13: =('BFI Scores'!AB13-'BFI Scores'!C13)^2 -> 0.060844444 | X13: =('BFI Scores'!AC13-'BFI Scores'!D13)^2 -> 0.0085049383 | Y13: =('BFI Scores'!AD13-'BFI Scores'!E13)^2 -> 0.1089 | Z13: =('BFI Scores'!AE13-'BFI Scores'!F13)^2 -> 0 | AA13: =('BFI Scores'!AF13-'BFI Scores'!B13)^2 -> 2.9155562 | AB13: =('BFI Scores'!AG13-'BFI Scores'!C13)^2 -> 0.091338272 | AC13: =('BFI Scores'!AH13-'BFI Scores'!D13)^2 -> 0.19457901 | AD13: =('BFI Scores'!AI13-'BFI Scores'!E13)^2 -> 3.6768062 | AE13: =('BFI Scores'!AJ13-'BFI Scores'!F13)^2 -> 1.5876 | AF13: =AVERAGE(B13:F13) -> 0.075120633 | AG13: =AVERAGE(G13:K13) -> 1.845348 | AH13: =AVERAGE(L13:P13) -> 1.3396567 | AI13: =AVERAGE(Q13:U13) -> 1.537176 | AJ13: =AVERAGE(V13:Z13) -> 0.17012988 | AK13: =AVERAGE(AA13:AE13) -> 1.693176
... A96: 99496 | B96: =('BFI Scores'!G96-'BFI Scores'!B96)^2 -> 1.500625 | C96: =('BFI Scores'!H96-'BFI Scores'!C96)^2 -> 0.021511111 | D96: =('BFI Scores'!I96-'BFI Scores'!D96)^2 -> 0.79012346 | E96: =('BFI Scores'!J96-'BFI Scores'!E96)^2 -> 0.05405625 | F96: =('BFI Scores'!K96-'BFI Scores'!F96)^2 -> 0.6241 | G96: =('BFI Scores'!L96-'BFI Scores'!B96)^2 -> 4.7851562 | H96: =('BFI Scores'!M96-'BFI Scores'!C96)^2 -> 1.0178568 | I96: =('BFI Scores'!N96-'BFI Scores'!D96)^2 -> 1.69 | J96: =('BFI Scores'!O96-'BFI Scores'!E96)^2 -> 3.222025 | K96: =('BFI Scores'!P96-'BFI Scores'!F96)^2 -> 0.01 | L96: =('BFI Scores'!Q96-'BFI Scores'!B96)^2 -> 0.4225 | M96: =('BFI Scores'!R96-'BFI Scores'!C96)^2 -> 0.039116049 | N96: =('BFI Scores'!S96-'BFI Scores'!D96)^2 -> 0.69444444 | O96: =('BFI Scores'!T96-'BFI Scores'!E96)^2 -> 0.245025 | P96: =('BFI Scores'!U96-'BFI Scores'!F96)^2 -> 0.7921 | Q96: =('BFI Scores'!V96-'BFI Scores'!B96)^2 -> 1.44 | R96: =('BFI Scores'!W96-'BFI Scores'!C96)^2 -> 0.44148642 | S96: =('BFI Scores'!X96-'BFI Scores'!D96)^2 -> 1.2593827 | T96: =('BFI Scores'!Y96-'BFI Scores'!E96)^2 -> 3.0888063 | U96: =('BFI Scores'!Z96-'BFI Scores'!F96)^2 -> 0.0004 | V96: =('BFI Scores'!AA96-'BFI Scores'!B96)^2 -> 0.74390625 | W96: =('BFI Scores'!AB96-'BFI Scores'!C96)^2 -> 0.0484 | X96: =('BFI Scores'!AC96-'BFI Scores'!D96)^2 -> 0.93444444 | Y96: =('BFI Scores'!AD96-'BFI Scores'!E96)^2 -> 0.002025 | Z96: =('BFI Scores'!AE96-'BFI Scores'!F96)^2 -> 0.4624 | AA96: =('BFI Scores'!AF96-'BFI Scores'!B96)^2 -> 3.0625 | AB96: =('BFI Scores'!AG96-'BFI Scores'!C96)^2 -> 1.0404 | AC96: =('BFI Scores'!AH96-'BFI Scores'!D96)^2 -> 3.2001235 | AD96: =('BFI Scores'!AI96-'BFI Scores'!E96)^2 -> 5.0963063 | AE96: =('BFI Scores'!AJ96-'BFI Scores'!F96)^2 -> 0.0049 | AF96: =AVERAGE(B96:F96) -> 0.59808316 | AG96: =AVERAGE(G96:K96) -> 2.1450076 | AH96: =AVERAGE(L96:P96) -> 0.4386371 | AI96: =AVERAGE(Q96:U96) -> 1.2460151 | AJ96: =AVERAGE(V96:Z96) -> 0.43823514 | AK96: =AVERAGE(AA96:AE96) -> 2.4808459
